#VRML_SIM R2023b utf8

EXTERNPROTO "https://raw.githubusercontent.com/cyberbotics/webots/R2025a/projects/objects/backgrounds/protos/TexturedBackground.proto"
EXTERNPROTO "https://raw.githubusercontent.com/cyberbotics/webots/R2025a/projects/objects/backgrounds/protos/TexturedBackgroundLight.proto"
EXTERNPROTO "https://raw.githubusercontent.com/cyberbotics/webots/R2025a/projects/objects/floors/protos/RectangleArena.proto"
EXTERNPROTO "https://raw.githubusercontent.com/cyberbotics/webots/R2023b/projects/objects/apartment_structure/protos/Wall.proto"
EXTERNPROTO "https://raw.githubusercontent.com/cyberbotics/webots/R2023b/projects/robots/mir/mir100/protos/Mir100.proto"

WorldInfo {
  basicTimeStep 4
}
Viewpoint {
  orientation -0.298713240474799 -0.6630391994389787 0.6864032488066786 5.138386810908679
  position -31.0741414965817 22.634877185726435 29.451179982735407
}
TexturedBackground {
}
RectangleArena {
  translation -10.8499 0.0557395 4.44089e-16
  rotation 0 0 1 -1.5707953071795862
  floorSize 9 24
  floorTileSize 1 1
  wallHeight 2
}
Wall {
  translation -8.22 2.82 -1.28
  rotation 0 0 1 3.14159
  name "wall(2)"
  size 0.2 3.5 2.4
}
Wall {
  translation -10.05 3.4 -1.28
  rotation 0 0 1 3.14159
  name "wall(4)"
  size 0.2 2.5 2.4
}
Wall {
  translation -10.443 3.55984 -1.28
  rotation 0 0 1 -2.8797953071795863
  name "wall(6)"
  size 0.2 3 2.4
}
Wall {
  translation -10.21 -1.56 -1.28
  rotation 0 0 -1 -1.5707953071795862
  name "wall(5)"
  size 0.2 1.9 2.4
}
Wall {
  translation -8.22 -2.75 -1.28
  rotation 0 0 1 3.14159
  name "wall(3)"
  size 0.2 3.5 2.4
}
Wall {
  translation -12.72 -2.75 -1.28
  rotation 0 0 1 3.14159
  name "wall(7)"
  size 0.2 3.5 2.4
}
Wall {
  translation -15.08 -2.75 -1.28
  rotation 0 0 1 3.14159
  name "wall(8)"
  size 0.2 3.5 2.4
}
Wall {
  translation -15.08 2.85 -1.28
  rotation 0 0 1 3.14159
  name "wall(9)"
  size 0.2 3.5 2.4
}
Wall {
  translation -17.63 1.03 1.2
  rotation -0.7071067811859252 1.326789589425184e-06 -0.7071067811859252 3.14159
  name "wall(12)"
  size 0.2 7.1 2.6
}
Wall {
  translation -17.52 2.85 -1.28
  rotation 0 0 1 3.14159
  name "wall(10)"
  size 0.2 3.5 2.4
}
Wall {
  translation -17.52 -2.83 -1.28
  rotation 0 0 1 3.14159
  name "wall(11)"
  size 0.2 3.5 2.4
}
TexturedBackgroundLight {
}
Robot {
  translation 0.23 0 0.36
  rotation 0 1 0 0
  children [
    Gyro {
    }
    Accelerometer {
      name "accel"
    }
    InertialUnit {
      name "imu"
    }
    Shape {
      appearance DEF ANEL_EXTERIOR_material PBRAppearance {
        baseColor 0.79216 0.81961 0.93333
        roughness 1
        metalness 0
      }
      geometry DEF ANEL_EXTERIOR Mesh {
        url [
          "../../ROBOT_LIDAR_STL/meshes/ANEL_EXTERIOR.STL"
        ]
      }
    }
    HingeJoint {
      jointParameters HingeJointParameters {
        axis 0 -1 -4e-06
        anchor 0 0 0.13
      }
      device [
        RotationalMotor {
          name "ANEL_INTERIOR_JOINT"
          maxTorque 10000
        }
        PositionSensor {
          name "ANEL_INTERIOR_JOINT_sensor"
        }
      ]
      endPoint Solid {
        translation 0 0 0.13
        rotation 1 0 0 1.5707999999997646
        children [
          Shape {
            appearance DEF ANEL_INTERIOR_material PBRAppearance {
              baseColor 0.79216 0.81961 0.93333
              roughness 1
              metalness 0
            }
            geometry DEF ANEL_INTERIOR Mesh {
              url [
                "../../ROBOT_LIDAR_STL/meshes/ANEL_INTERIOR.STL"
              ]
            }
          }
          HingeJoint {
            jointParameters HingeJointParameters {
              axis 0.999915 0 0
            }
            device [
              RotationalMotor {
                name "PLATAFORMA_JOINT"
                maxTorque 10000
              }
              PositionSensor {
                name "PLATAFORMA_JOINT_sensor"
              }
            ]
            endPoint Solid {
              translation 0 0 1.0842021724855044e-18
              rotation 6.215902063253501e-10 -1.578724717072009e-11 1 0.050797000157756504
              children [
                Lidar {
                  translation 0 0.032 0
                  rotation -0.9993948383490694 0.024596331514252213 -0.02459629153507128 1.57079633
                  horizontalResolution 500
                  fieldOfView 6.28318
                  verticalFieldOfView 0.1
                  numberOfLayers 1
                  minRange 0.02
                  maxRange 12
                }
                Shape {
                  appearance DEF PLATAFORMA_material PBRAppearance {
                    baseColor 0.79216 0.81961 0.93333
                    roughness 1
                    metalness 0
                  }
                  geometry DEF PLATAFORMA Mesh {
                    url [
                      "../../ROBOT_LIDAR_STL/meshes/PLATAFORMA.STL"
                    ]
                  }
                }
              ]
              name "PLATAFORMA"
              boundingObject USE PLATAFORMA
              physics Physics {
                density -1
                mass 0.095647
                centerOfMass [
                  0.00032 0.009451 5.9e-05
                ]
                inertiaMatrix [
                  3.6155e-05 4.2386e-05 3.7022e-05
                  1.4164e-07 5.2965e-09 1.7595e-07
                ]
              }
            }
          }
        ]
        name "ANEL_INTERIOR"
        boundingObject USE ANEL_INTERIOR
        physics Physics {
          density -1
          mass 0.080301
          centerOfMass [
            0.029334 -0.000373 -0.001107
          ]
          inertiaMatrix [
            8.6625e-05 0.0002005 0.00011994
            1.4464e-06 -2.2357e-06 2.8305e-08
          ]
        }
      }
    }
  ]
  name "ROBOTLIDARABS"
  boundingObject Cylinder {
    height 0.005
    radius 0.092
  }
  physics Physics {
    density -1
    mass 0.32949
    centerOfMass [
      -0.001685 0.057135 -0.010584
    ]
    inertiaMatrix [
      0.0022513 0.0021283 0.002012
      4.0443e-05 -4.1317e-05 0.00025534
    ]
  }
  controller "my_controller"
}
Wall {
  translation -3.87 2.87138 -0.92
  rotation 0 0 -1 0.523598
  size 0.2 4 2.5
}
Wall {
  translation -4.71 -3.05 -1.24
  rotation 0 0 1 1.01503e-06
  name "wall(1)"
  size 0.2 4 2.4
}
Mir100 {
  translation 0.14 -0.01 0
  rotation 0 0 1 3.14159
}
